<?xml version="1.0"?>

<robot xmlns:xacro="http://ros.org/wiki/xacro">

    <xacro:property name="M_PI" value="3.1415926535897931"/>


    <xacro:macro name="lrs_camera_gimbal"
                 params="name parent_link link_name image_topic camera_info_topic frame_id update_rate im_width im_height im_format hfov_deg far_clip z_offset">


        <link name="${link_name}">
            <inertial>
                <mass value="0.0010"/>
                <origin xyz="0 0 0" rpy="0 0 0"/>
                <inertia ixx="0.0001" ixy="0" ixz="0" iyy="0.0001" iyz="0" izz="0.0001"/>
            </inertial>
            <visual>
                <origin xyz="0 0 0" rpy="0 0 0"/>
                <geometry>
                    <mesh filename="package://lrs_halmstad/models/zenmuse_z3/meshes/zenmuse_z3.dae"/>
                </geometry>
            </visual>
            <collision>
                <origin xyz="0 0 0" rpy="0 0 0"/>
                <geometry>
                    <mesh filename="package://lrs_halmstad/models/zenmuse_z3/meshes/zenmuse_z3.stl"/>
                </geometry>
            </collision>
        </link>

        <joint name="::camera_joint" type="floating">
            <origin xyz="0.12 0 ${z_offset}" rpy="0 0 0"/>
            <parent link="::${parent_link}"/>
            <child link="::${link_name}"/>
        </joint>

        <joint name="camera_optical_joint" type="floating">
            <origin xyz="0 0 0" rpy="${-M_PI/2} 0.0 ${-M_PI/2}"/>
            <parent link="${link_name}"/>
            <child link="camera_optical_frame"/>
        </joint>

        <link name="camera_optical_frame"/>

        <gazebo reference="${link_name}">
            <sensor type="camera" name="camera_sensor">
                <camera>
                    <!-- <pose>0.027 0 -0.027 0 1.57 0</pose> -->
                    <!-- <pose>0.027 0 -0.027 0 1.57 0</pose> -->
                    <pose>0.027 0 -0.027 0 0 0</pose>
                    <horizontal_fov>${hfov_deg * M_PI/180.0}</horizontal_fov>
                    <image>
                        <format>${im_format}</format>
                        <width>${im_width}</width>
                        <height>${im_height}</height>
                    </image>
                    <clip>
                        <near>0.01</near>
                        <far>${far_clip}</far>
                    </clip>
                </camera>
                <update_rate>${update_rate}</update_rate>
                <always_on>1</always_on>
                <visualize>true</visualize>
                <topic>${image_topic}</topic>
             </sensor>                
                <!-- plugin name="camera_controller_${name}" filename="libgazebo_ros_camera.so">
                    <cameraName>${name}</cameraName>
                    <alwaysOn>true</alwaysOn>
                    <updateRate>${update_rate}</updateRate>
                    <imageTopicName>${image_topic}</imageTopicName>
                    <cameraInfoTopicName>${camera_info_topic}</cameraInfoTopicName>
                    <frameName>${frame_id}</frameName>
                </plugin -->
        </gazebo>
    </xacro:macro>



</robot>
