<?xml version='1.0'?>
<sdf version="1.6">
    <model name="X2">
        <pose>0 0 0.063494 0 0 0</pose>
        <enable_wind>1</enable_wind>
        <link name="base">
            <inertial>
                <pose>0.011999 0.002 0.066996 0 -0 0</pose>
                <mass>16.524</mass>
                <inertia>
                    <ixx>0.320605</ixx>
                    <ixy>-0.000800023</ixy>
                    <ixz>0.0163992</ixz>
                    <iyy>0.399205</iyy>
                    <iyz>-0.000900133</iyz>
                    <izz>0.455501</izz>
                </inertia>
            </inertial>
            <collision name="chassis_collision">
                <pose>0 0 0.092 0 -0 0</pose>
                <geometry>
                    <box>
                        <size>0.42 0.31 0.184</size>
                    </box>
                </geometry>
            </collision>
            <visual name="chassis_visual">
                <pose>0 0 -0.0655 1.5708 0 -1.5708</pose>
                <geometry>
                    <mesh>
                        <uri>https://fuel.gazebosim.org/1.0/openrobotics/models/x2%20ugv/4/files/meshes/x2_chassis.dae</uri>
                    </mesh>
                </geometry>
            </visual>
            <visual name="navsat_visual_1">
                <pose>-0.18 0.126 0.1895 0 -0 0</pose>
                <geometry>
                    <cylinder>
                        <length>0.016</length>
                        <radius>0.026</radius>
                    </cylinder>
                </geometry>
            </visual>
            <visual name="center_left_headlight_visual">
                <pose>0.22 0.05 0.0845 0 -0 -3.14159</pose>
                <geometry>
                    <mesh>
                        <uri>https://fuel.gazebosim.org/1.0/openrobotics/models/x2%20ugv/4/files/meshes/headlight.dae</uri>
                    </mesh>
                </geometry>
            </visual>
            <visual name="left_headlight_visual">
                <pose>0.22 0.145 0.0845 0 -0 -3.14159</pose>
                <geometry>
                    <mesh>
                        <uri>https://fuel.gazebosim.org/1.0/openrobotics/models/x2%20ugv/4/files/meshes/headlight.dae</uri>
                    </mesh>
                </geometry>
            </visual>
            <visual name="center_right_headlight_visual">
                <pose>0.22 -0.05 0.0845 0 -0 -3.14159</pose>
                <geometry>
                    <mesh>
                        <uri>https://fuel.gazebosim.org/1.0/openrobotics/models/x2%20ugv/4/files/meshes/headlight.dae</uri>
                    </mesh>
                </geometry>
            </visual>
            <visual name="right_headlight_visual">
                <pose>0.22 -0.145 0.0845 0 -0 -3.14159</pose>
                <geometry>
                    <mesh>
                        <uri>https://fuel.gazebosim.org/1.0/openrobotics/models/x2%20ugv/4/files/meshes/headlight.dae</uri>
                    </mesh>
                </geometry>
            </visual>
            <light name="left_light_source" type="spot">
                <pose>0.273 0.145 0.141 3.14159 1.56859 0</pose>
                <attenuation>
                    <range>25</range>
                    <linear>0</linear>
                    <constant>0.1</constant>
                    <quadratic>0.005</quadratic>
                </attenuation>
                <diffuse>0.8 0.8 0.5 1</diffuse>
                <specular>0.8 0.8 0.5 1</specular>
                <spot>
                    <inner_angle>1</inner_angle>
                    <outer_angle>1.1</outer_angle>
                    <falloff>1</falloff>
                </spot>
                <direction>0 0 -1</direction>
                <cast_shadows>1</cast_shadows>
            </light>
            <light name="right_light_source" type="spot">
                <pose>0.273 -0.145 0.141 3.14159 1.56859 0</pose>
                <attenuation>
                    <range>25</range>
                    <linear>0</linear>
                    <constant>0.1</constant>
                    <quadratic>0.005</quadratic>
                </attenuation>
                <diffuse>0.8 0.8 0.5 1</diffuse>
                <specular>0.8 0.8 0.5 1</specular>
                <spot>
                    <inner_angle>1</inner_angle>
                    <outer_angle>1.1</outer_angle>
                    <falloff>1</falloff>
                </spot>
                <direction>0 0 -1</direction>
            </light>
            <light name="center_left_light_source" type="spot">
                <pose>0.273 0.05 0.141 3.14159 1.56859 0</pose>
                <attenuation>
                    <range>25</range>
                    <linear>0</linear>
                    <constant>0.1</constant>
                    <quadratic>0.005</quadratic>
                </attenuation>
                <diffuse>0.8 0.8 0.5 1</diffuse>
                <specular>0.8 0.8 0.5 1</specular>
                <spot>
                    <inner_angle>1</inner_angle>
                    <outer_angle>1.1</outer_angle>
                    <falloff>1</falloff>
                </spot>
                <direction>0 0 -1</direction>
                <cast_shadows>1</cast_shadows>
            </light>
            <light name="center_right_light_source" type="spot">
                <pose>0.273 0.05 0.141 3.14159 1.56859 0</pose>
                <attenuation>
                    <range>25</range>
                    <linear>0</linear>
                    <constant>0.1</constant>
                    <quadratic>0.005</quadratic>
                </attenuation>
                <diffuse>0.8 0.8 0.5 1</diffuse>
                <specular>0.8 0.8 0.5 1</specular>
                <spot>
                    <inner_angle>1</inner_angle>
                    <outer_angle>1.1</outer_angle>
                    <falloff>1</falloff>
                </spot>
                <direction>0 0 -1</direction>
                <cast_shadows>1</cast_shadows>
            </light>
            <sensor name="lidar" type="gpu_ray">
                <pose>0.2 0 0.2 0 0 0</pose>
                <always_on>1</always_on>
                <update_rate>20</update_rate>
                <visualize>true</visualize>
                <lidar>
                    <scan>
                        <horizontal>
                            <samples>360</samples>
                            <resolution>1</resolution>
                            <min_angle>-3.14159</min_angle>
                            <max_angle>3.14159</max_angle>
                        </horizontal>
                    </scan>
                    <range>
                        <min>0.12</min>
                        <max>25.0</max>
                        <resolution>0.01</resolution>
                    </range>
                    <noise>
                        <type>gaussian</type>
                        <mean>0.0</mean>
                        <stddev>0.01</stddev>
                    </noise>
                </lidar>
            </sensor>
        </link>
        <link name="front_left_wheel">
            <pose>0.131 0.187795 0.0345 0 -0 0</pose>
            <inertial>
                <mass>0.477</mass>
                <inertia>
                    <ixx>0.0013</ixx>
                    <ixy>0</ixy>
                    <ixz>0</ixz>
                    <iyy>0.0024</iyy>
                    <iyz>0</iyz>
                    <izz>0.0013</izz>
                </inertia>
            </inertial>
            <collision name="collision">
                <pose>0 0 0 1.5708 -0 0</pose>
                <geometry>
                    <cylinder>
                        <length>0.04</length>
                        <radius>0.098</radius>
                    </cylinder>
                </geometry>
                <surface>
                    <friction>
                        <ode>
                            <mu>1.0</mu>
                            <mu2>0.2</mu2>
                            <fdir1>1 0 0</fdir1>
                        </ode>
                    </friction>
                </surface>
            </collision>
            <visual name="visual">
                <pose>0 0 0 1.5708 -0 0</pose>
                <geometry>
                    <mesh>
                        <uri>https://fuel.gazebosim.org/1.0/openrobotics/models/x2%20ugv/4/files/meshes/x2_wheel_left.dae</uri>
                    </mesh>
                </geometry>
            </visual>
        </link>
        <link name="front_right_wheel">
            <pose>0.131 -0.187795 0.0345 0 -0 0</pose>
            <inertial>
                <mass>0.477</mass>
                <inertia>
                    <ixx>0.0013</ixx>
                    <ixy>0</ixy>
                    <ixz>0</ixz>
                    <iyy>0.0024</iyy>
                    <iyz>0</iyz>
                    <izz>0.0013</izz>
                </inertia>
            </inertial>
            <collision name="collision">
                <pose>0 0 0 1.5708 -0 0</pose>
                <geometry>
                    <cylinder>
                        <length>0.04</length>
                        <radius>0.098</radius>
                    </cylinder>
                </geometry>
                <surface>
                    <friction>
                        <ode>
                            <mu>1.0</mu>
                            <mu2>0.2</mu2>
                            <fdir1>1 0 0</fdir1>
                        </ode>
                    </friction>
                </surface>
            </collision>
            <visual name="visual">
                <pose>0 0 0 1.5708 -0 0</pose>
                <geometry>
                    <mesh>
                        <uri>https://fuel.gazebosim.org/1.0/openrobotics/models/x2%20ugv/4/files/meshes/x2_wheel_right.dae</uri>
                    </mesh>
                </geometry>
            </visual>
        </link>
        <link name="rear_left_wheel">
            <pose>-0.131 0.187795 0.0345 0 -0 0</pose>
            <inertial>
                <mass>0.477</mass>
                <inertia>
                    <ixx>0.0013</ixx>
                    <ixy>0</ixy>
                    <ixz>0</ixz>
                    <iyy>0.0024</iyy>
                    <iyz>0</iyz>
                    <izz>0.0013</izz>
                </inertia>
            </inertial>
            <collision name="collision">
                <pose>0 0 0 1.5708 -0 0</pose>
                <geometry>
                    <cylinder>
                        <length>0.04</length>
                        <radius>0.098</radius>
                    </cylinder>
                </geometry>
                <surface>
                    <friction>
                        <ode>
                            <mu>1.0</mu>
                            <mu2>0.2</mu2>
                            <fdir1>1 0 0</fdir1>
                        </ode>
                    </friction>
                </surface>
            </collision>
            <visual name="visual">
                <pose>0 0 0 1.5708 -0 0</pose>
                <geometry>
                    <mesh>
                        <uri>https://fuel.gazebosim.org/1.0/openrobotics/models/x2%20ugv/4/files/meshes/x2_wheel_left.dae</uri>
                    </mesh>
                </geometry>
            </visual>
        </link>
        <link name="rear_right_wheel">
            <pose>-0.131 -0.187795 0.0345 0 -0 0</pose>
            <inertial>
                <mass>0.477</mass>
                <inertia>
                    <ixx>0.0013</ixx>
                    <ixy>0</ixy>
                    <ixz>0</ixz>
                    <iyy>0.0024</iyy>
                    <iyz>0</iyz>
                    <izz>0.0013</izz>
                </inertia>
            </inertial>
            <collision name="collision">
                <pose>0 0 0 1.5708 -0 0</pose>
                <geometry>
                    <cylinder>
                        <length>0.04</length>
                        <radius>0.098</radius>
                    </cylinder>
                </geometry>
                <surface>
                    <friction>
                        <ode>
                            <mu>1.0</mu>
                            <mu2>0.2</mu2>
                            <fdir1>1 0 0</fdir1>
                        </ode>
                    </friction>
                </surface>
            </collision>
            <visual name="visual">
                <pose>0 0 0 1.5708 -0 0</pose>
                <geometry>
                    <mesh>
                        <uri>https://fuel.gazebosim.org/1.0/openrobotics/models/x2%20ugv/4/files/meshes/x2_wheel_right.dae</uri>
                    </mesh>
                </geometry>
            </visual>
        </link>
        <joint name="front_left_wheel_joint" type="revolute">
            <child>front_left_wheel</child>
            <parent>base</parent>
            <axis>
                <xyz>0 1 0</xyz>
                <limit>
                    <lower>-1e+16</lower>
                    <upper>1e+16</upper>
                </limit>
                <use_parent_model_frame>1</use_parent_model_frame>
            </axis>
        </joint>
        <joint name="rear_left_wheel_joint" type="revolute">
            <parent>base</parent>
            <child>rear_left_wheel</child>
            <axis>
                <xyz>0 1 0</xyz>
                <limit>
                    <lower>-1.79769e+308</lower>
                    <upper>+1.79769e+308</upper>
                </limit>
            </axis>
        </joint>
        <joint name="rear_right_wheel_joint" type="revolute">
            <parent>base</parent>
            <child>rear_right_wheel</child>
            <axis>
                <xyz>0 1 0</xyz>
                <limit>
                    <lower>-1.79769e+308</lower>
                    <upper>+1.79769e+308</upper>
                </limit>
            </axis>
        </joint>
        <joint name="front_right_wheel_joint" type="revolute">
            <parent>base</parent>
            <child>front_right_wheel</child>
            <axis>
                <xyz>0 1 0</xyz>
                <limit>
                    <lower>-1.79769e+308</lower>
                    <upper>+1.79769e+308</upper>
                </limit>
            </axis>
        </joint>
        <plugin filename="gz-sim-diff-drive-system"
                name="gz::sim::systems::DiffDrive">
            <left_joint>rear_left_wheel_joint</left_joint>
            <right_joint>rear_right_wheel_joint</right_joint>
            <wheel_separation>0.3756</wheel_separation>
            <wheel_radius>0.098</wheel_radius>
            <topic>/x2_ugv/cmd_vel</topic>
        </plugin>
    </model>
</sdf>
